testOne (__main__.TestArryCalc) ... FAIL
testTwo (__main__.TestArryCalc) ... ok
testThree (__main__.TestArryCalc) ... ok

======================================================================
FAIL: testOne (__main__.TestArryCalc)
----------------------------------------------------------------------
Traceback (most recent call last):
  File "test_F3.py", line 48, in testOne
    self.assertEqual(1, b1.first())
AssertionError: 1 != 2

----------------------------------------------------------------------
Ran 3 tests in 0.050s

FAILED (failures=1)
