testOne (__main__.TestArryCalc) ... ok
testTwo (__main__.TestArryCalc) ... FAIL
testThree (__main__.TestArryCalc) ... FAIL

======================================================================
FAIL: testTwo (__main__.TestArryCalc)
----------------------------------------------------------------------
Traceback (most recent call last):
  File "test_F2.py", line 61, in testTwo
    self.assertEqual(3, b2.last())
AssertionError: 3 != 0

======================================================================
FAIL: testThree (__main__.TestArryCalc)
----------------------------------------------------------------------
Traceback (most recent call last):
  File "test_F2.py", line 74, in testThree
    self.assertEqual(2, b3.avg())
AssertionError: 2 != 1.0

----------------------------------------------------------------------
Ran 3 tests in 0.048s

FAILED (failures=2)
