testOne_a1 (__main__.TestArryCalc) ... ok
testOne_b1 (__main__.TestArryCalc) ... FAIL
testOne_c1 (__main__.TestArryCalc) ... FAIL
testTwo_a2 (__main__.TestArryCalc) ... ok
testTwo_b2 (__main__.TestArryCalc) ... ok
testTwo_c2 (__main__.TestArryCalc) ... ok
testThree_a3 (__main__.TestArryCalc) ... ok
testThree_b3 (__main__.TestArryCalc) ... ok
testThree_c3 (__main__.TestArryCalc) ... ok


======================================================================
FAIL: testOne_b1 (__main__.TestArryCalc)
----------------------------------------------------------------------
Traceback (most recent call last):
  File "test_F3.py", line 46, in testOne_b1
    self.assertEqual(1, b1.first())
AssertionError: 1 != 2

======================================================================
FAIL: testOne_c1 (__main__.TestArryCalc)
----------------------------------------------------------------------
Traceback (most recent call last):
  File "test_F3.py", line 51, in testOne_c1
    self.assertEqual(1, c1.first())
AssertionError: 1 != 4

----------------------------------------------------------------------
Ran 9 tests in 0.063s

FAILED (failures=2)
