test_avg (__main__.TestArryCalc) ... ok
test_first (__main__.TestArryCalc) ... FAIL
test_getter (__main__.TestArryCalc) ... ok
test_last (__main__.TestArryCalc) ... ok

======================================================================
FAIL: test_first (__main__.TestArryCalc)
----------------------------------------------------------------------
Traceback (most recent call last):
  File "test_F3.py", line 60, in test_first
    self.assertEqual(1, b1.first())
AssertionError: 1 != 2

----------------------------------------------------------------------
Ran 4 tests in 0.061s

FAILED (failures=1)
