test_avg (__main__.TestArryCalc) ... FAIL
test_first (__main__.TestArryCalc) ... ok
test_getter (__main__.TestArryCalc) ... ERROR
test_last (__main__.TestArryCalc) ... FAIL

======================================================================
ERROR: test_getter (__main__.TestArryCalc)
----------------------------------------------------------------------
Traceback (most recent call last):
  File "test_F1.py", line 40, in test_getter
    test_getter_a = self.adapterSetting(0,0,0, TC, TC + '_a')
AttributeError: 'TestArryCalc' object has no attribute 'adapterSetting'

======================================================================
FAIL: test_avg (__main__.TestArryCalc)
----------------------------------------------------------------------
Traceback (most recent call last):
  File "test_F1.py", line 87, in test_avg
    self.assertEqual(2, test_avg_b.avg())
AssertionError: 2 != 1.0

======================================================================
FAIL: test_last (__main__.TestArryCalc)
----------------------------------------------------------------------
Traceback (most recent call last):
  File "test_F1.py", line 73, in test_last
    self.assertEqual(3, test_last_b.last())
AssertionError: 3 != 0

----------------------------------------------------------------------
Ran 4 tests in 0.056s

FAILED (failures=2, errors=1)
