test_avg (__main__.TestArryCalc) ... ok
test_first (__main__.TestArryCalc) ... ok
test_getter (__main__.TestArryCalc) ... ok
test_last (__main__.TestArryCalc) ... FAIL

======================================================================
FAIL: test_last (__main__.TestArryCalc)
----------------------------------------------------------------------
Traceback (most recent call last):
  File "test_F4.py", line 73, in test_last
    self.assertEqual(3, test_last_b.last())
AssertionError: 3 != 1

----------------------------------------------------------------------
Ran 4 tests in 0.089s

FAILED (failures=1)
